Workbook

Sheet START HERE
A1: WS 3.0 — EVERY USE CASE, AND WHY CHAT-FIRST BEATS WS 2.0
B3: What this is
B4: The claim | C4: WS 3.0 is a rebuild of the EZ workspace as three chat-first apps — client, expert, SWAT — on the Conversation OS shell described in the framework/surfaces vision doc. This workbook lists every use case the product has to serve, says where each one lives in our UI, names the WS 2.0 equivalent, and rules on which is better.
B5: The comparison | C5: WS 2.0 is the shipped product. It is a table-and-modal application: a Live Requests table, a detail pane, a Gantt, and a modal per action. It is not a strawman — 10 of the 112 use cases below are marked 'WS 2.0 better' and a whole tab is given to the gaps we have not closed.
B6: Who it is for | C6: Anyone assessing whether chat-first is the right shape for this product. It is written to be checked, not to be believed — every claim carries a source and every weakness is stated rather than left to be found.
B8: How to read it
B9: 1 · Use cases | C9: THE MAIN SHEET. All 112 use cases across the whole project. For each: the actor, the PRD stage it belongs to, why it exists at all, the surface and component that serves it in our build, how it opens, the WS 2.0 equivalent, a verdict, and whether it is built in the prototype.
B10: 2 · Component comparison | C10: 30 UI components side by side. WS 2.0's treatment, ours, which surface ours sits on, WHY it sits there, why it is better — and a column that names where WS 2.0 still wins. Every row has that last column filled in honestly, and 10 of the 30 concede a point.
B11: 3 · Screens × surfaces | C11: 19 screens mapped onto Framework B's six surfaces (B1–B6) in the vision doc's own format, so the mapping can be checked against the source rather than taken on trust.
B12: 4 · Rules that bind | C12: The 18 invariants any UI here must honour, each traced to the PRD clause or SOP it comes from. If a design decision on tab 1 or 2 looks arbitrary, it is usually one of these.
B13: 5 · Honest gaps | C13: 15 places where we are behind, where both products are behind, or where our own build has a known bug. Includes a live tension between chat-first and the PRD's own 'ambient AI, not a chatbot' rule.
B14: 6 · Summary | C14: Counts, computed with formulas over tab 1 so they move if a verdict is edited. Change a verdict on tab 1 and this tab follows.
B16: The verdict scale
B17: Better · new | C17: The use case has no WS 2.0 equivalent at all, and chat-first is what made it cheap to add. 42 of 112.
B18: Better | C18: Both products serve it; ours takes fewer steps, states more, or removes a class of error. 25 of 112.
B19: Parity | C19: Genuinely equivalent. Different shape, same outcome and roughly the same effort. 21 of 112.
B20: WS 2.0 better | C20: They do it better than we do, today. 10 of 112 — listed rather than argued away.
B21: Gap on both | C21: Neither product serves it. 9 of 112. These are the roadmap, not a scoring dispute.
B22: Out of scope | C22: Belongs to WS admin or platform, not to any of the three apps. 5 of 112.
B24: The argument in five lines
B25: 1. The room is the ground | C25: The vision doc's Framework B: conversation is the ground; structure is summoned as spaces over it. Every node of the work graph — request, assignment, activity — is a room. Navigation and structure become the same object, so there is nothing to keep in sync.
B26: 2. Decisions live where the context is | C26: In WS 2.0 you read state in a pane and act in a modal. Here the card that tells you carries the buttons that resolve it. That is one gesture instead of three, and it is why the same shell serves a client approving a price and an expert accepting an offer.
B27: 3. The exception is the row | C27: Our lists say 'Tariq silent 4h — SOP-15 says offer onward', not 'Delayed'. A table of equal-weight rows makes you open things to triage; a list of stated exceptions lets you triage without opening anything.
B28: 4. One commercial trigger | C28: Verify — and only verify — bills the client and pays the performer. WS 2.0 invoices on completion, which is the defect the PRD calls D4. This is a model change the UI simply expresses.
B29: 5. It cost less to add the missing half | C29: Retainers, wallets, disputes, budget pace, private peer channels, an archive: 42 use cases with no WS 2.0 equivalent, most of them a card and a form rather than a screen. That is the real dividend of chat-first — the marginal cost of a new use case.
B31: Sources
B32: Vision | C32: docs/reference/WS3-framework-surfaces-vision.pdf — Framework B · Conversation OS, surfaces B1–B6, and the ground/summoned distinction. Framework A · Structured Cockpit is the documented alternative; B is what we built.
B33: PRD | C33: docs/tenant-zero/spec.md — lifecycle stages E1–E15, the Request → Assignment → Activity work graph, and the FR-numbered rules cited on tab 4.
B34: WS 2.0 | C34: 14 screenshots of the shipped product shared in this project: Live Requests, request detail, Create New Request, Edit Request, Gantt, Flowchart, Create Activity, Delivery, Feedback, Collaborators, Splitter, Edit Log, Client rating, Tools.
B35: The build | C35: design/ws3-client-chat.html · design/ws3-expert-chat.html · design/ws3-swat-chat.html — the three prototypes the 'Built?' column refers to.
B37: How to challenge this
B38: Attack the verdicts | C38: Tab 1 column J. Every one is a judgement. If 'Better' should be 'Parity' on a row, change it — tab 6 recomputes.
B39: Attack the placement | C39: Tab 2 column E is the reason a component sits on the surface it does. If the reason does not follow from the vision doc, the placement is wrong.
B40: Attack the coverage | C40: 112 use cases is a claim of completeness. The fastest disproof is a job one of these three actors does that appears nowhere on tab 1.
B41: What we already concede | C41: Scanning at volume, bulk operations, the Gantt, lifecycle states, allocation UI, agent discoverability. All on tab 5, none of them dressed up.

Sheet 1 · Use cases
A1: EVERY USE CASE IN THE PROJECT · 112 rows · client, expert, SWAT, admin
A2: # | B2: Actor | C2: PRD stage | D2: Use case | E2: Why it exists | F2: Our surface | G2: Our component | H2: How it opens | I2: WS 2.0 equivalent | J2: Verdict | K2: Built?
A3: CL-01 | B3: Client | C3: E5 Intake | D3: Raise a request in their own words | E3: The brief is a sentence, not a form. Making them classify it first is the tax WS 2.0 charged. | F3: B5 prompt | G3: Composer + ambient mapping | H3: Inline | I3: Create New Request modal: Deliver to, CC, Instructions, Files, Delivery, Entity, Charge code, Project, Send to | J3: Better | K3: Yes
A4: CL-02 | B4: Client | C4: E5 Intake | D4: Attach input files and reference files separately | E4: Input is what gets worked on; reference is context. Conflating them corrupts the unit count. | F4: B3 spaces | G4: Files space — three shelves | H4: Top drawer | I4: Two drop zones on the modal | J4: Parity | K4: Yes
A5: CL-03 | B5: Client | C5: E5 Intake | D5: Set the deadline they actually need | E5: A date given late is worse than a date refused early. | F5: B5 prompt | G5: Date chip on the intake card | H5: Inline | I5: Requested Delivery field + repeat selector | J5: Parity | K5: Yes
A6: CL-04 | B6: Client | C6: E5 Intake | D6: Charge the work to the right entity and cost centre | E6: Finance reconciles by charge code; getting it wrong means a re-issue. | F6: B3 spaces | G6: Resolved from account config, shown on the plan card | H6: Inline | I6: Entity + Charge Code dropdowns on the request form | J6: WS 2.0 better | K6: Partial
A7: CL-05 | B7: Client | C7: E5 Intake | D7: Send the same brief from email or a connected tool | E7: Most briefs never touch our UI. Intake has to meet them where they are. | F7: B4 conversation | G7: Request appears as a room, source noted | H7: Inline | I7: Email adapter, Phrase adapter | J7: Parity | K7: Simulated
A8: CL-06 | B8: Client | C8: E5 Intake | D8: Reuse a request that worked before | E8: Repeat work is most work. Re-typing it is waste. | F8: B3 spaces | G8: Templates in the Library drawer | H8: Side drawer | I8: Duplicate on the request menu | J8: WS 2.0 better | K8: No
A9: CL-07 | B9: Client | C9: E7 Ratify | D9: See the plan, the price and the date before anything runs | E9: This is the authorisation. It has to be complete and unambiguous. | F9: B3 spaces | G9: Scope & price sheet | H9: Top drawer | I9: Assignment rows on the Gantt, price not shown to client | J9: Better | K9: Yes
A10: CL-08 | B10: Client | C10: E7 Ratify | D10: Approve scope in one action | E10: Human touchpoint 1 of 2. Everything else is pushed, not pulled. | F10: B4 conversation | G10: Decision card with Approve on it | H10: Inline | I10: Confirm on a modal | J10: Better | K10: Yes
A11: CL-09 | B11: Client | C11: E7 Ratify | D11: Adjust the scope before approving | E11: A plan you cannot edit is a plan you reject. | F11: B3 spaces | G11: Inline edit on the scope sheet | H11: Top drawer | I11: Edit Request modal | J11: Parity | K11: Partial
A12: CL-10 | B12: Client | C12: E9 Execution | D12: See progress without asking anyone | E12: The status-chasing email is the single most common client behaviour. Kill the cause. | F12: B2 list + B3 spaces | G12: Per-request roll-up, per-file progress | H12: Inline | I12: Progress % column and per-assignment bars | J12: Parity | K12: Yes
A13: CL-11 | B13: Client | C13: E9 Execution | D13: Receive an interim draft | E13: Seeing it early is how a wrong direction gets caught cheaply. | F13: B4 conversation | G13: Interim event, border-safe and watermarked | H13: Inline | I13: Delivery panel versions | J13: Better | K13: Yes
... A114: AD-05 | B114: Operator L0 | C114: E1 Provision | D114: Provision a workspace, set tier and modules | E114: No tenant content ever visible at this level. | F114: Operator console | G114: Out of scope | H114: - | I114: Not seen | J114: Out of scope | K114: No

Sheet 2 · Component comparison
A1: COMPONENT BY COMPONENT · WS 2.0 vs chat-first · why each one sits where it does
A2: Component | B2: WS 2.0 treatment | C2: Our treatment | D2: Surface | E2: Why it sits there | F2: Why it is better | G2: Where WS 2.0 still wins
A3: The place work lives | B3: A Live Requests table: ID, Request, Status, Progress, Notifications, Owner, Due Date — grouped by month, with search and a filter icon. | C3: A list of rooms, at-risk first, each carrying the exception in plain words and a state badge in ops language (Ratify, Stalled, Verify D+2). | D3: B2 list + context | E3: The list is the only surface a person sees before they know what they are doing. It has to answer 'what needs me' rather than 'what exists'. A table answers the second question well and the first one badly, because every row looks equally important. | F3: A row states the exception and the SOP, not a status word: 'Tariq silent 4h - SOP-15 says offer onward'. You can triage without opening anything. | G3: Above roughly a dozen rows a table wins on scanning. We built a board for SWAT and reverted it - see the Honest gaps tab.
A4: Request detail | B4: A detail pane beside the list: request ID, deliver-to, CC, instructions, input and reference files, requested delivery, entity, charge code, with an Edit link opening a modal. | C4: The request is a room. Its facts arrive as cards in the stream; its structure is summoned as spaces over the same ground. | D4: B4 conversation + B3 spaces | E4: The vision doc's whole distinction is what is ground and what is summoned. In Framework B the room is the ground, so a request cannot be a document you visit - it is a place you are in, and its detail is pulled in on demand. | F4: Reading a fact and acting on it are the same gesture. In WS 2.0 the detail pane is read-only and every action is a separate modal. | G4: A modal that shows all fields at once is faster to audit than cards you summon one at a time.
A5: Request → assignment → activity | B5: Implied by indentation on the Gantt (ASM- rows under REQ-), plus a Flowchart view. Two views of the same thing, neither of them the navigation. | C5: The tree IS the navigation: a request opens to its assignments, an assignment to its activities, and every node is a room with its own conversation. | D5: B2 list + context | E5: This is the only object EZ actually manages, and the vision doc says each node is a room. Putting the hierarchy in the list means the structure and the navigation are the same thing, so there is nothing to keep in sync. | F5: Two taps deep, nothing rendered until asked for. Each level is addressable, so a conversation attaches to the node it is about - which is what makes a dispute filable against an activity rather than a request. | G5: -
A6: The plan against time | B6: A first-class Gantt: hour-level columns, a 12-hour zoom control, tier and assignment filters, per-row start and due, assignee, and a Today marker. | C6: A plan space summoned into the room, showing the activities on one axis with today marked and the dependencies that are not yours greyed. | D6: B3 spaces | E6: A Gantt is a scheduling instrument, not a reading surface. Summoning it keeps the room readable when you do not need it and gives it the full width when you do. | F6: The performer's version shows what their bar gates - Sana cannot start until this lands - which is the only reason a performer needs a Gantt at all. | G6: WS 2.0's is better: zoomable, filterable, hour-level. Ours is a strip. For a desk running forty requests theirs is the stronger tool.
A7: The splitter | B7: A Plan / Splitter toggle on the request. The mechanism that turns one file into parts and parts into activities. | C7: A splitter space: cut into 2, 3, 4 or 6, preview the ranges and the cost per part, remainder to part one, apply and the activities are written into the tree. | D7: B3 spaces | E7: Every number downstream comes from here - the unit count, the price, the payout. It belongs beside the tree it writes into, not in a separate mode. | F7: The preview states the arithmetic before it commits, including where the remainder goes, so the split is auditable at the moment it is made rather than in a log afterwards. | G7: -
A8: Editing the plan | B8: Modal forms: Create/Edit Assignment (offering, language, template, urgency, unit type and count, entity, charge code, invoice code) and Create/Edit Activity (skill, units, start, deadline, estimated vs committed, input files with tool and access, required outputs with mandatory and map-to, allocation with rating and availability). | C8: Per-node menus on the tree - edit, add activity, add sibling or nested assignment, pause, duplicate, cancel - opening the same field set as a card in the room. | D8: B3 spaces + popover | E8: Editing belongs where the thing being edited is visible. A modal hides the tree you are reasoning about; a card in the room keeps it above you. | F8: The consequence updates live: cancel a 700 activity and the margin moves 50% to 63% while you decide. WS 2.0 shows you the result after you save. | G8: WS 2.0's field coverage is still ahead at request level, and its menus include a Timeline Manager we have no answer to.
A9: Alerts and attention | B9: Notification count badges on each request row, and a bell. | C9: A bar under the room header carrying that room's top alert with the action on it; a sheet listing everything, grouped into Needs you, For your awareness, and Handled. | D9: B6 ambient AI | E9: An alert is about a node, so it belongs on the node. Home is the only place that sees everything - anywhere else, an alert from elsewhere is noise. | F9: The bar carries the resolving action, so an alert is cleared where it happened rather than navigated to. A badge tells you a number; this tells you the move. | G9: -
A10: Decisions | B10: Modals with Confirm and Cancel. | C10: Decision cards in the stream: a coloured spine by severity, the consequence in prose, and the actions on the card itself. | D10: B4 conversation | E10: A decision has a before and an after, and both belong in the record. A modal has neither - it appears from nowhere and leaves no trace. | F10: The card states what happens if you do nothing, which is the information a modal never carries. It also stays in the room afterwards as the reason the thing happened. | G10: -
A11: Conversation | B11: A Chats side panel, scoped by Request / Assignments / Experts, with unread dots and file attachments. | C11: The conversation is the ground the whole app stands on. Every other surface is summoned over it. | D11: B4 conversation | E11: This is Framework B's founding choice and the vision doc's one distinction that drives everything: the room is the ground; structure is summoned. | F11: Nothing has to be kept in sync between a record and a discussion about the record, because they are the same stream. WS 2.0 already had chat - it was simply beside the work rather than under it. | G11: Their panel is honest about scale: an unread list of rooms is easier to work than a stream when you hold forty of them.
A12: Knowing who hears you | B12: Implicit in which chat you opened. | C12: A scope chip on the prompt naming the audience and its visibility - the owner sees it, SWAT means the owner sees it too, a peer means neither, AI means nobody. | D12: B5 prompt | E12: Ambiguity about audience is the single biggest failure mode of a chat-first product. If people are unsure who hears them, they either overshare across a boundary or stop using it. | F12: Visibility is stated per option at the moment of choosing, not inferred from which panel you happen to be in. | G12: -
A13: A private word with a peer | B13: None. Everything is on the record. | C13: A private strand inside the activity, lilac and locked, headed with who can and cannot see it - and promotable into the room in one action. | D13: B5 prompt + B4 | E13: The question an expert most needs to ask is the one they cannot ask on the record. Denying it does not prevent it; it moves it to WhatsApp where EZ can neither help nor learn from it. | F13: Private by content, never secret in existence, and escalatable. A side-channel you can promote beats one you have to hide. | G13: -
... A32: Bulk work | B32: Select All with Cancel, Pause, Delete and Duplicate across activities. | C32: Not built. | D32: - | E32: - | F32: - | G32: WS 2.0 wins outright. At forty rows bulk is the difference between a tool and a chore.
A34: Reading the colours | B34: Grey = WS 2.0. Blue = ours. Amber in the last column = a point they still win. 10 of the 30 rows carry one; the rest read '-' because we could not find one, not because we did not look.

Sheet 3 · Screens x surfaces
A1: SCREENS x FRAMEWORK B SURFACES · the vision doc's own format, filled in from the build
A2: App | B2: Screen | C2: B1 · section nav | D2: B2 · list + context | E2: B3 · spaces | F2: B4 · conversation | G2: B5 · prompt | H2: B6 · ambient AI
A3: Client | B3: Home / workspace | C3: Home active | D3: Rooms, at-risk first; money as a rail item | E3: Morning brief tiles, plan, my requests | F3: The workspace agent stream | G3: Ask or act; scope = workspace | H3: Ranked decisions in the stream
A4: Client | B4: Request room | C4: Requests active | D4: This request selected; its assignments beneath | E4: Scope sheet, files, deliverables, instructions | F4: The request stream, both sides of the boundary | G4: Message; scope = request; boundary internal or client-visible | H4: Plan proposed, date at risk, delivery ready
A5: Client | B5: Delivery & verify | C5: Requests active | D5: The delivered request | E5: Deliverables with versions and downloads | F5: Verify card in the stream | G5: Verify, flag an issue, request a revision | H5: Nothing bills until you verify
A6: Client | B6: Money | C6: Money active | D6: Wallet, work history, statements, tracker | E6: The open money section | F6: Money agent stream | G6: Ask about a bill; run a command | H6: Overdue, expiring credits, budget pace
A7: Client | B7: Retainer | C7: Requests active | D7: The engagement, its periods beneath | E7: Usage against commitment | F7: Period stream | G7: Message; scope = engagement | H7: Period closes in 9 days
A8: Expert | B8: Home / my work | C8: Home active | D8: Pinned SWAT, then the tree of what she holds | E8: My work table, utilisation, the plan | F8: The workspace stream | G8: Ask or act; scope = workspace | H8: Offer, unit change, QA fail
A9: Expert | B9: Activity room | C9: My work active | D9: The activity, under its assignment and request | E9: Brief, plan, files, deliveries, log | F9: The activity stream, private strands inline | G9: Message; scope = owner / desk / peer / AI | H9: This will not clear 18:00
A10: Expert | B10: Offer | C10: My work active | D10: The offered activity | E10: The brief, before accepting | F10: Offer card with why-you and the clock | G10: Ask before accepting | H10: Re-proposes to Priya in 2h 39m
A11: Expert | B11: Earnings | C11: Money active | D11: Earnings, payouts, rate card | E11: The open money section | F11: Money stream | G11: Ask about a line or a payout | H11: Released, pending verify
A12: Expert | B12: Archive | C12: My work active | D12: Closed rooms, collapsed to a count | E12: - | F12: The room as it was, read-only | G12: Disabled, with the reason | H12: -
A13: SWAT | B13: Home / the floor | C13: Home active | D13: Rooms at-risk first; intake pinned | E13: Floor brief, the floor list, upcoming | F13: The workspace stream | G13: Ask or act; scope = the floor | H13: 6 need your hand
... A21: SWAT | B21: People / capacity | C21: Team active | D21: People and agents | E21: Capacity | F21: The person stream | G21: Message; scope = person | H21: Over capacity
A23: Note | B23: B1 section nav · B2 list + context · B3 spaces summoned over the ground · B4 conversation (the ground) · B5 context-adaptive prompt with a scope indicator · B6 ambient AI. Source: WS3-framework-surfaces-vision.pdf. On mobile Framework B flips the ground: the list becomes the surface and the conversation a detented drawer.

Sheet 4 · Rules that bind
A1: THE RULES ANY UI HERE MUST HONOUR · each traced to its clause
A2: # | B2: Rule | C2: What it forces in the UI | D2: Source
A3: R-01 | B3: AI proposes, a human ratifies | C3: Nothing becomes an assignment without a human tap. No auto-start anywhere. | D3: PRD E6/E7, FR-7.1
A4: R-02 | B4: Verify is the only commercial trigger | C4: Nothing bills before the tap. One billable event fans out to invoice and payout together. | D4: PRD E10/E11, FR-11.1, the D4 fix
A5: R-03 | B5: A performer is paid off verified work | C5: Independent of whether the client has paid. A client dispute never claws back a verified payout. | D5: PRD FR-11.2, E13 F5
A6: R-04 | B6: The client never sees who does the work | C6: Not the expert, not the sub-vendor. Milestones, never machinery. | D6: PRD E14, boundary rules
A7: R-05 | B7: Roles attach per node, not per user | C7: One person can be the performer on an activity and the owner of the assignment above it. Access is computed per node. | D7: PRD S2, added 9 Aug
A8: R-06 | B8: Deliver is the mandatory last activity | C8: Every assignment has one, minted automatically. It cannot be the thing you cancel. | D8: PRD E7, work graph
A9: R-07 | B9: Wallet: deduct at create, settle at verify, refund on cancel | C9: Prepaid work is funded by credits; work beyond them falls to terms. | D9: PRD FR-11.4
A10: R-08 | B10: A funded wallet is an intake precondition | C10: Publishing work that cannot be paid for is a false start. Negative balance is per-tenant config. | D10: PRD E11 edge cases
A11: R-09 | B11: Rework is not new scope | C11: A QA round-trip adds no units and claws nothing back. | D11: PRD E9, FR-9.5
A12: R-10 | B12: A fix is free, an addition is priced | C12: Stated before the client chooses, not after. | D12: PRD E13 F1
A13: R-11 | B13: Reassignment fee-split; the workspace never funds the overrun | C13: An EZ rule expressed as config. | D13: PRD E13 F2
... A20: R-18 | B20: Files are pointers, bytes live in the enclave | C20: Brokered access with JIT credentials and expiry. | D20: PRD FR-11.8, security.md

Sheet 5 · Honest gaps
A1: WHERE WE ARE BEHIND · stated, not argued away
A2: Gap | B2: Who wins | C2: The position | D2: Status
A3: Scanning at volume | B3: WS 2.0 wins | C3: Their Live Requests table beats a chat list above roughly a dozen rows. We built a floor board for SWAT on 9 Aug and reverted it the same day at the user's call. The honest position is that this is unresolved, not solved. | D3: Open
A4: Bulk operations | B4: WS 2.0 wins | C4: Select All with Cancel / Pause / Delete / Duplicate. We have none. At forty rows this is the difference between a tool and a chore. | D4: Not built
A5: The Gantt | B5: WS 2.0 wins | C5: Hour-level columns, a zoom control and tier filters. Ours is a strip with a today marker. | D5: Partial
A6: Request lifecycle states | B6: WS 2.0 wins | C6: Live / Drafts / Delivered / Archived. We have Draft and an archive, and no month grouping. | D6: Partial
A7: Allocation UI | B7: WS 2.0 wins | C7: Their Create Activity shows the candidate, their rating and their availability at the moment of choosing. We show none of it - the biggest single gap on the SWAT side. | D7: Not built
A8: Timeline Manager | B8: WS 2.0 only | C8: On their request menu. We have no equivalent and have not established what it does. | D8: Unknown
A9: Agent discoverability | B9: WS 2.0 wins | C9: Tools tiles on their home screen make the agents browsable. Ours only appear where already allocated. | D9: Not built
A10: Ambient AI vs chat-first | B10: Tension with the PRD | C10: PRD S3 says 'Ambient AI, not a chatbot - AI appears inline as suggestions a human approves, never a separate assistant to converse with.' Every app we have built has a workspace agent you talk to. This is a deliberate departure and needs explicit sign-off rather than being discovered later. | D10: Needs a decision
A11: Cascade and invariants | B11: Our bug | C11: Cancelling an assignment leaves its activities live and its cost in the margin. Pausing does not cascade. The mandatory Deliver can be cancelled. Reproduced 9 Aug; fix parked. | D11: Known, parked
A12: Room lifecycle exits | B12: Our gap | C12: Verify is the only way a room closes. Cancel, pause, a declined offer and reassignment all leave a dead room behind. | D12: Known, parked
A13: Intake edge cases | B13: Gap on both | C13: Ambiguous sender disambiguation, email dedupe, and flagging a missing or past deadline before composing. Neither product does these. | D13: Not built
... A17: Dispute inbox | B17: Our gap | C17: The expert app raises unit disputes and timeline recommendations. Nothing in SWAT receives either. Asked for 7 Aug, still open. | D17: Not built
A19: Why this tab exists | B19: A comparison with no losses in it is marketing. Six of these are places WS 2.0 is simply better today, two are our own bugs reproduced on 9 Aug, and one is a conflict between chat-first and the PRD's own 'ambient AI, not a chatbot' rule that needs a decision rather than a defence.

Sheet 6 · Summary
A1: SUMMARY · every number here is a formula over tab 1, not a typed count
B3: Verdict by actor
C4: Better · new | D4: Better | E4: Parity | F4: WS 2.0 better | G4: Gap on both | H4: Out of scope | I4: Total
B5: Client | C5: =COUNTIFS('1 · Use cases'!$B$3:$B$114,$B5,'1 · Use cases'!$J$3:$J$114,C$4) -> 8 | D5: =COUNTIFS('1 · Use cases'!$B$3:$B$114,$B5,'1 · Use cases'!$J$3:$J$114,D$4) -> 11 | E5: =COUNTIFS('1 · Use cases'!$B$3:$B$114,$B5,'1 · Use cases'!$J$3:$J$114,E$4) -> 11 | F5: =COUNTIFS('1 · Use cases'!$B$3:$B$114,$B5,'1 · Use cases'!$J$3:$J$114,F$4) -> 4 | G5: =COUNTIFS('1 · Use cases'!$B$3:$B$114,$B5,'1 · Use cases'!$J$3:$J$114,G$4) -> 0 | H5: =COUNTIFS('1 · Use cases'!$B$3:$B$114,$B5,'1 · Use cases'!$J$3:$J$114,H$4) -> 0 | I5: =SUM(C5:H5) -> 34
B6: Expert | C6: =COUNTIFS('1 · Use cases'!$B$3:$B$114,$B6,'1 · Use cases'!$J$3:$J$114,C$4) -> 18 | D6: =COUNTIFS('1 · Use cases'!$B$3:$B$114,$B6,'1 · Use cases'!$J$3:$J$114,D$4) -> 7 | E6: =COUNTIFS('1 · Use cases'!$B$3:$B$114,$B6,'1 · Use cases'!$J$3:$J$114,E$4) -> 5 | F6: =COUNTIFS('1 · Use cases'!$B$3:$B$114,$B6,'1 · Use cases'!$J$3:$J$114,F$4) -> 0 | G6: =COUNTIFS('1 · Use cases'!$B$3:$B$114,$B6,'1 · Use cases'!$J$3:$J$114,G$4) -> 2 | H6: =COUNTIFS('1 · Use cases'!$B$3:$B$114,$B6,'1 · Use cases'!$J$3:$J$114,H$4) -> 0 | I6: =SUM(C6:H6) -> 32
B7: SWAT | C7: =COUNTIFS('1 · Use cases'!$B$3:$B$114,$B7,'1 · Use cases'!$J$3:$J$114,C$4) -> 16 | D7: =COUNTIFS('1 · Use cases'!$B$3:$B$114,$B7,'1 · Use cases'!$J$3:$J$114,D$4) -> 7 | E7: =COUNTIFS('1 · Use cases'!$B$3:$B$114,$B7,'1 · Use cases'!$J$3:$J$114,E$4) -> 5 | F7: =COUNTIFS('1 · Use cases'!$B$3:$B$114,$B7,'1 · Use cases'!$J$3:$J$114,F$4) -> 6 | G7: =COUNTIFS('1 · Use cases'!$B$3:$B$114,$B7,'1 · Use cases'!$J$3:$J$114,G$4) -> 7 | H7: =COUNTIFS('1 · Use cases'!$B$3:$B$114,$B7,'1 · Use cases'!$J$3:$J$114,H$4) -> 0 | I7: =SUM(C7:H7) -> 41
B8: WS Admin | C8: =COUNTIFS('1 · Use cases'!$B$3:$B$114,$B8,'1 · Use cases'!$J$3:$J$114,C$4) -> 0 | D8: =COUNTIFS('1 · Use cases'!$B$3:$B$114,$B8,'1 · Use cases'!$J$3:$J$114,D$4) -> 0 | E8: =COUNTIFS('1 · Use cases'!$B$3:$B$114,$B8,'1 · Use cases'!$J$3:$J$114,E$4) -> 0 | F8: =COUNTIFS('1 · Use cases'!$B$3:$B$114,$B8,'1 · Use cases'!$J$3:$J$114,F$4) -> 0 | G8: =COUNTIFS('1 · Use cases'!$B$3:$B$114,$B8,'1 · Use cases'!$J$3:$J$114,G$4) -> 0 | H8: =COUNTIFS('1 · Use cases'!$B$3:$B$114,$B8,'1 · Use cases'!$J$3:$J$114,H$4) -> 4 | I8: =SUM(C8:H8) -> 4
B9: Operator L0 | C9: =COUNTIFS('1 · Use cases'!$B$3:$B$114,$B9,'1 · Use cases'!$J$3:$J$114,C$4) -> 0 | D9: =COUNTIFS('1 · Use cases'!$B$3:$B$114,$B9,'1 · Use cases'!$J$3:$J$114,D$4) -> 0 | E9: =COUNTIFS('1 · Use cases'!$B$3:$B$114,$B9,'1 · Use cases'!$J$3:$J$114,E$4) -> 0 | F9: =COUNTIFS('1 · Use cases'!$B$3:$B$114,$B9,'1 · Use cases'!$J$3:$J$114,F$4) -> 0 | G9: =COUNTIFS('1 · Use cases'!$B$3:$B$114,$B9,'1 · Use cases'!$J$3:$J$114,G$4) -> 0 | H9: =COUNTIFS('1 · Use cases'!$B$3:$B$114,$B9,'1 · Use cases'!$J$3:$J$114,H$4) -> 1 | I9: =SUM(C9:H9) -> 1
B10: Total | C10: =SUM(C5:C9) -> 42 | D10: =SUM(D5:D9) -> 25 | E10: =SUM(E5:E9) -> 21 | F10: =SUM(F5:F9) -> 10 | G10: =SUM(G5:G9) -> 9 | H10: =SUM(H5:H9) -> 5 | I10: =SUM(I5:I9) -> 112
B11: Green verdicts are ours to defend; 'WS 2.0 better' and 'Gap on both' are on tab 5.
B13: Build state by actor
C14: Yes | D14: Partial | E14: Simulated | F14: No | G14: Total
B15: Client | C15: =COUNTIFS('1 · Use cases'!$B$3:$B$114,$B15,'1 · Use cases'!$K$3:$K$114,C$14) -> 27 | D15: =COUNTIFS('1 · Use cases'!$B$3:$B$114,$B15,'1 · Use cases'!$K$3:$K$114,D$14) -> 3 | E15: =COUNTIFS('1 · Use cases'!$B$3:$B$114,$B15,'1 · Use cases'!$K$3:$K$114,E$14) -> 1 | F15: =COUNTIFS('1 · Use cases'!$B$3:$B$114,$B15,'1 · Use cases'!$K$3:$K$114,F$14) -> 3 | G15: =SUM(C15:F15) -> 34
B16: Expert | C16: =COUNTIFS('1 · Use cases'!$B$3:$B$114,$B16,'1 · Use cases'!$K$3:$K$114,C$14) -> 28 | D16: =COUNTIFS('1 · Use cases'!$B$3:$B$114,$B16,'1 · Use cases'!$K$3:$K$114,D$14) -> 2 | E16: =COUNTIFS('1 · Use cases'!$B$3:$B$114,$B16,'1 · Use cases'!$K$3:$K$114,E$14) -> 0 | F16: =COUNTIFS('1 · Use cases'!$B$3:$B$114,$B16,'1 · Use cases'!$K$3:$K$114,F$14) -> 2 | G16: =SUM(C16:F16) -> 32
B17: SWAT | C17: =COUNTIFS('1 · Use cases'!$B$3:$B$114,$B17,'1 · Use cases'!$K$3:$K$114,C$14) -> 28 | D17: =COUNTIFS('1 · Use cases'!$B$3:$B$114,$B17,'1 · Use cases'!$K$3:$K$114,D$14) -> 3 | E17: =COUNTIFS('1 · Use cases'!$B$3:$B$114,$B17,'1 · Use cases'!$K$3:$K$114,E$14) -> 0 | F17: =COUNTIFS('1 · Use cases'!$B$3:$B$114,$B17,'1 · Use cases'!$K$3:$K$114,F$14) -> 10 | G17: =SUM(C17:F17) -> 41
B18: WS Admin | C18: =COUNTIFS('1 · Use cases'!$B$3:$B$114,$B18,'1 · Use cases'!$K$3:$K$114,C$14) -> 0 | D18: =COUNTIFS('1 · Use cases'!$B$3:$B$114,$B18,'1 · Use cases'!$K$3:$K$114,D$14) -> 0 | E18: =COUNTIFS('1 · Use cases'!$B$3:$B$114,$B18,'1 · Use cases'!$K$3:$K$114,E$14) -> 0 | F18: =COUNTIFS('1 · Use cases'!$B$3:$B$114,$B18,'1 · Use cases'!$K$3:$K$114,F$14) -> 4 | G18: =SUM(C18:F18) -> 4
B19: Operator L0 | C19: =COUNTIFS('1 · Use cases'!$B$3:$B$114,$B19,'1 · Use cases'!$K$3:$K$114,C$14) -> 0 | D19: =COUNTIFS('1 · Use cases'!$B$3:$B$114,$B19,'1 · Use cases'!$K$3:$K$114,D$14) -> 0 | E19: =COUNTIFS('1 · Use cases'!$B$3:$B$114,$B19,'1 · Use cases'!$K$3:$K$114,E$14) -> 0 | F19: =COUNTIFS('1 · Use cases'!$B$3:$B$114,$B19,'1 · Use cases'!$K$3:$K$114,F$14) -> 1 | G19: =SUM(C19:F19) -> 1
B20: Total | C20: =SUM(C15:C19) -> 83 | D20: =SUM(D15:D19) -> 8 | E20: =SUM(E15:E19) -> 1 | F20: =SUM(F15:F19) -> 20 | G20: =SUM(G15:G19) -> 112
B21: 'Simulated' means the path exists in the prototype but is stubbed. 'No' rows are mostly the tab 5 gaps.
B23: Verdict by PRD stage
C24: Better · new | D24: Better | E24: Parity | F24: WS 2.0 better | G24: Gap on both | H24: Out of scope | I24: Total
B25: Cross | C25: =COUNTIFS('1 · Use cases'!$C$3:$C$114,$B25,'1 · Use cases'!$J$3:$J$114,C$24) -> 7 | D25: =COUNTIFS('1 · Use cases'!$C$3:$C$114,$B25,'1 · Use cases'!$J$3:$J$114,D$24) -> 3 | E25: =COUNTIFS('1 · Use cases'!$C$3:$C$114,$B25,'1 · Use cases'!$J$3:$J$114,E$24) -> 4 | F25: =COUNTIFS('1 · Use cases'!$C$3:$C$114,$B25,'1 · Use cases'!$J$3:$J$114,F$24) -> 2 | G25: =COUNTIFS('1 · Use cases'!$C$3:$C$114,$B25,'1 · Use cases'!$J$3:$J$114,G$24) -> 2 | H25: =COUNTIFS('1 · Use cases'!$C$3:$C$114,$B25,'1 · Use cases'!$J$3:$J$114,H$24) -> 0 | I25: =SUM(C25:H25) -> 18
B26: E1 Provision | C26: =COUNTIFS('1 · Use cases'!$C$3:$C$114,$B26,'1 · Use cases'!$J$3:$J$114,C$24) -> 0 | D26: =COUNTIFS('1 · Use cases'!$C$3:$C$114,$B26,'1 · Use cases'!$J$3:$J$114,D$24) -> 0 | E26: =COUNTIFS('1 · Use cases'!$C$3:$C$114,$B26,'1 · Use cases'!$J$3:$J$114,E$24) -> 0 | F26: =COUNTIFS('1 · Use cases'!$C$3:$C$114,$B26,'1 · Use cases'!$J$3:$J$114,F$24) -> 0 | G26: =COUNTIFS('1 · Use cases'!$C$3:$C$114,$B26,'1 · Use cases'!$J$3:$J$114,G$24) -> 0 | H26: =COUNTIFS('1 · Use cases'!$C$3:$C$114,$B26,'1 · Use cases'!$J$3:$J$114,H$24) -> 1 | I26: =SUM(C26:H26) -> 1
B27: E10 Delivery | C27: =COUNTIFS('1 · Use cases'!$C$3:$C$114,$B27,'1 · Use cases'!$J$3:$J$114,C$24) -> 6 | D27: =COUNTIFS('1 · Use cases'!$C$3:$C$114,$B27,'1 · Use cases'!$J$3:$J$114,D$24) -> 1 | E27: =COUNTIFS('1 · Use cases'!$C$3:$C$114,$B27,'1 · Use cases'!$J$3:$J$114,E$24) -> 4 | F27: =COUNTIFS('1 · Use cases'!$C$3:$C$114,$B27,'1 · Use cases'!$J$3:$J$114,F$24) -> 0 | G27: =COUNTIFS('1 · Use cases'!$C$3:$C$114,$B27,'1 · Use cases'!$J$3:$J$114,G$24) -> 0 | H27: =COUNTIFS('1 · Use cases'!$C$3:$C$114,$B27,'1 · Use cases'!$J$3:$J$114,H$24) -> 0 | I27: =SUM(C27:H27) -> 11
B28: E11 Money | C28: =COUNTIFS('1 · Use cases'!$C$3:$C$114,$B28,'1 · Use cases'!$J$3:$J$114,C$24) -> 9 | D28: =COUNTIFS('1 · Use cases'!$C$3:$C$114,$B28,'1 · Use cases'!$J$3:$J$114,D$24) -> 4 | E28: =COUNTIFS('1 · Use cases'!$C$3:$C$114,$B28,'1 · Use cases'!$J$3:$J$114,E$24) -> 0 | F28: =COUNTIFS('1 · Use cases'!$C$3:$C$114,$B28,'1 · Use cases'!$J$3:$J$114,F$24) -> 0 | G28: =COUNTIFS('1 · Use cases'!$C$3:$C$114,$B28,'1 · Use cases'!$J$3:$J$114,G$24) -> 0 | H28: =COUNTIFS('1 · Use cases'!$C$3:$C$114,$B28,'1 · Use cases'!$J$3:$J$114,H$24) -> 0 | I28: =SUM(C28:H28) -> 13
B29: E12 Retainer | C29: =COUNTIFS('1 · Use cases'!$C$3:$C$114,$B29,'1 · Use cases'!$J$3:$J$114,C$24) -> 3 | D29: =COUNTIFS('1 · Use cases'!$C$3:$C$114,$B29,'1 · Use cases'!$J$3:$J$114,D$24) -> 0 | E29: =COUNTIFS('1 · Use cases'!$C$3:$C$114,$B29,'1 · Use cases'!$J$3:$J$114,E$24) -> 0 | F29: =COUNTIFS('1 · Use cases'!$C$3:$C$114,$B29,'1 · Use cases'!$J$3:$J$114,F$24) -> 0 | G29: =COUNTIFS('1 · Use cases'!$C$3:$C$114,$B29,'1 · Use cases'!$J$3:$J$114,G$24) -> 1 | H29: =COUNTIFS('1 · Use cases'!$C$3:$C$114,$B29,'1 · Use cases'!$J$3:$J$114,H$24) -> 0 | I29: =SUM(C29:H29) -> 4
B30: E13 Change | C30: =COUNTIFS('1 · Use cases'!$C$3:$C$114,$B30,'1 · Use cases'!$J$3:$J$114,C$24) -> 2 | D30: =COUNTIFS('1 · Use cases'!$C$3:$C$114,$B30,'1 · Use cases'!$J$3:$J$114,D$24) -> 0 | E30: =COUNTIFS('1 · Use cases'!$C$3:$C$114,$B30,'1 · Use cases'!$J$3:$J$114,E$24) -> 1 | F30: =COUNTIFS('1 · Use cases'!$C$3:$C$114,$B30,'1 · Use cases'!$J$3:$J$114,F$24) -> 2 | G30: =COUNTIFS('1 · Use cases'!$C$3:$C$114,$B30,'1 · Use cases'!$J$3:$J$114,G$24) -> 2 | H30: =COUNTIFS('1 · Use cases'!$C$3:$C$114,$B30,'1 · Use cases'!$J$3:$J$114,H$24) -> 0 | I30: =SUM(C30:H30) -> 7
B31: E2 Config | C31: =COUNTIFS('1 · Use cases'!$C$3:$C$114,$B31,'1 · Use cases'!$J$3:$J$114,C$24) -> 0 | D31: =COUNTIFS('1 · Use cases'!$C$3:$C$114,$B31,'1 · Use cases'!$J$3:$J$114,D$24) -> 0 | E31: =COUNTIFS('1 · Use cases'!$C$3:$C$114,$B31,'1 · Use cases'!$J$3:$J$114,E$24) -> 0 | F31: =COUNTIFS('1 · Use cases'!$C$3:$C$114,$B31,'1 · Use cases'!$J$3:$J$114,F$24) -> 0 | G31: =COUNTIFS('1 · Use cases'!$C$3:$C$114,$B31,'1 · Use cases'!$J$3:$J$114,G$24) -> 0 | H31: =COUNTIFS('1 · Use cases'!$C$3:$C$114,$B31,'1 · Use cases'!$J$3:$J$114,H$24) -> 2 | I31: =SUM(C31:H31) -> 2
B32: E3 People | C32: =COUNTIFS('1 · Use cases'!$C$3:$C$114,$B32,'1 · Use cases'!$J$3:$J$114,C$24) -> 0 | D32: =COUNTIFS('1 · Use cases'!$C$3:$C$114,$B32,'1 · Use cases'!$J$3:$J$114,D$24) -> 0 | E32: =COUNTIFS('1 · Use cases'!$C$3:$C$114,$B32,'1 · Use cases'!$J$3:$J$114,E$24) -> 0 | F32: =COUNTIFS('1 · Use cases'!$C$3:$C$114,$B32,'1 · Use cases'!$J$3:$J$114,F$24) -> 0 | G32: =COUNTIFS('1 · Use cases'!$C$3:$C$114,$B32,'1 · Use cases'!$J$3:$J$114,G$24) -> 0 | H32: =COUNTIFS('1 · Use cases'!$C$3:$C$114,$B32,'1 · Use cases'!$J$3:$J$114,H$24) -> 1 | I32: =SUM(C32:H32) -> 1
B33: E4 Relationships | C33: =COUNTIFS('1 · Use cases'!$C$3:$C$114,$B33,'1 · Use cases'!$J$3:$J$114,C$24) -> 0 | D33: =COUNTIFS('1 · Use cases'!$C$3:$C$114,$B33,'1 · Use cases'!$J$3:$J$114,D$24) -> 0 | E33: =COUNTIFS('1 · Use cases'!$C$3:$C$114,$B33,'1 · Use cases'!$J$3:$J$114,E$24) -> 0 | F33: =COUNTIFS('1 · Use cases'!$C$3:$C$114,$B33,'1 · Use cases'!$J$3:$J$114,F$24) -> 0 | G33: =COUNTIFS('1 · Use cases'!$C$3:$C$114,$B33,'1 · Use cases'!$J$3:$J$114,G$24) -> 0 | H33: =COUNTIFS('1 · Use cases'!$C$3:$C$114,$B33,'1 · Use cases'!$J$3:$J$114,H$24) -> 1 | I33: =SUM(C33:H33) -> 1
B34: E5 Intake | C34: =COUNTIFS('1 · Use cases'!$C$3:$C$114,$B34,'1 · Use cases'!$J$3:$J$114,C$24) -> 1 | D34: =COUNTIFS('1 · Use cases'!$C$3:$C$114,$B34,'1 · Use cases'!$J$3:$J$114,D$24) -> 3 | E34: =COUNTIFS('1 · Use cases'!$C$3:$C$114,$B34,'1 · Use cases'!$J$3:$J$114,E$24) -> 4 | F34: =COUNTIFS('1 · Use cases'!$C$3:$C$114,$B34,'1 · Use cases'!$J$3:$J$114,F$24) -> 2 | G34: =COUNTIFS('1 · Use cases'!$C$3:$C$114,$B34,'1 · Use cases'!$J$3:$J$114,G$24) -> 3 | H34: =COUNTIFS('1 · Use cases'!$C$3:$C$114,$B34,'1 · Use cases'!$J$3:$J$114,H$24) -> 0 | I34: =SUM(C34:H34) -> 13
B35: E6 Compose | C35: =COUNTIFS('1 · Use cases'!$C$3:$C$114,$B35,'1 · Use cases'!$J$3:$J$114,C$24) -> 1 | D35: =COUNTIFS('1 · Use cases'!$C$3:$C$114,$B35,'1 · Use cases'!$J$3:$J$114,D$24) -> 0 | E35: =COUNTIFS('1 · Use cases'!$C$3:$C$114,$B35,'1 · Use cases'!$J$3:$J$114,E$24) -> 0 | F35: =COUNTIFS('1 · Use cases'!$C$3:$C$114,$B35,'1 · Use cases'!$J$3:$J$114,F$24) -> 0 | G35: =COUNTIFS('1 · Use cases'!$C$3:$C$114,$B35,'1 · Use cases'!$J$3:$J$114,G$24) -> 1 | H35: =COUNTIFS('1 · Use cases'!$C$3:$C$114,$B35,'1 · Use cases'!$J$3:$J$114,H$24) -> 0 | I35: =SUM(C35:H35) -> 2
B36: E7 Ratify | C36: =COUNTIFS('1 · Use cases'!$C$3:$C$114,$B36,'1 · Use cases'!$J$3:$J$114,C$24) -> 1 | D36: =COUNTIFS('1 · Use cases'!$C$3:$C$114,$B36,'1 · Use cases'!$J$3:$J$114,D$24) -> 3 | E36: =COUNTIFS('1 · Use cases'!$C$3:$C$114,$B36,'1 · Use cases'!$J$3:$J$114,E$24) -> 2 | F36: =COUNTIFS('1 · Use cases'!$C$3:$C$114,$B36,'1 · Use cases'!$J$3:$J$114,F$24) -> 0 | G36: =COUNTIFS('1 · Use cases'!$C$3:$C$114,$B36,'1 · Use cases'!$J$3:$J$114,G$24) -> 0 | H36: =COUNTIFS('1 · Use cases'!$C$3:$C$114,$B36,'1 · Use cases'!$J$3:$J$114,H$24) -> 0 | I36: =SUM(C36:H36) -> 6
... B38: E9 Execution | C38: =COUNTIFS('1 · Use cases'!$C$3:$C$114,$B38,'1 · Use cases'!$J$3:$J$114,C$24) -> 6 | D38: =COUNTIFS('1 · Use cases'!$C$3:$C$114,$B38,'1 · Use cases'!$J$3:$J$114,D$24) -> 9 | E38: =COUNTIFS('1 · Use cases'!$C$3:$C$114,$B38,'1 · Use cases'!$J$3:$J$114,E$24) -> 6 | F38: =COUNTIFS('1 · Use cases'!$C$3:$C$114,$B38,'1 · Use cases'!$J$3:$J$114,F$24) -> 3 | G38: =COUNTIFS('1 · Use cases'!$C$3:$C$114,$B38,'1 · Use cases'!$J$3:$J$114,G$24) -> 0 | H38: =COUNTIFS('1 · Use cases'!$C$3:$C$114,$B38,'1 · Use cases'!$J$3:$J$114,H$24) -> 0 | I38: =SUM(C38:H38) -> 24
B39: Total | C39: =SUM(C25:C38) -> 42 | D39: =SUM(D25:D38) -> 25 | E39: =SUM(E25:E38) -> 21 | F39: =SUM(F25:F38) -> 10 | G39: =SUM(G25:G38) -> 9 | H39: =SUM(H25:H38) -> 5 | I39: =SUM(I25:I38) -> 112
B40: Stages are the PRD's own lifecycle (docs/tenant-zero/spec.md, E1-E15). 'Cross' is anything that is not stage-bound.
B42: Headline
B43: Use cases in the project | C43: =COUNTA('1 · Use cases'!$A$3:$A$114) -> 112
B44: Built in a prototype today | C44: =COUNTIF('1 · Use cases'!$K$3:$K$114,"Yes") -> 83
B45: Where chat-first wins | C45: =COUNTIF('1 · Use cases'!$J$3:$J$114,"Better · new")+COUNTIF('1 · Use cases'!$J$3:$J$114,"Better") -> 67
...
